Workbook

Sheet Summary
B1: E&C · Shipment Cost & Market Datasheet
B2: Invoice HS25E1112W1 · Henan Spark Machinery Co. Ltd · dated 12 Nov 2025 · CIF Colombo · Qingdao → Colombo
B4: Assumptions (edit the yellow cells)
B5: Exchange rate paid (LKR / USD) | C5: 305 | D5: ← your actual TT / customs rate (≈ Nov 2025)
B6: Duty factor on CIF (landed ÷ CIF, ex-VAT) | C6: 1.26 | D6: ← CID 15% + PAL 7.5% + SSCL 2.5% (VAT 18% recoverable)
B8: Invoice line totals — CIF Colombo
B9: Line | C9: USD | D9: LKR (CIF) | E9: LKR (landed) | F9: Hydraulic?
B10: Connectors 22611/22691/22611D | C10: 828 | D10: =C10*Summary!$C$5 -> 252540 | E10: =D10*Summary!$C$6 -> 318200.4 | F10: Yes
B11: Connectors 22612/22692/10011N | C11: 1032 | D11: =C11*Summary!$C$5 -> 314760 | E11: =D11*Summary!$C$6 -> 396597.6 | F11: Yes
B12: Connectors 90011/72011/20011 | C12: 70 | D12: =C12*Summary!$C$5 -> 21350 | E12: =D12*Summary!$C$6 -> 26901 | F12: Yes
B13: Connectors FL/87391 (flanges) | C13: 120 | D13: =C13*Summary!$C$5 -> 36600 | E13: =D13*Summary!$C$6 -> 46116 | F13: Yes
B14: Rubber hose (R1/R2/4SP/4SH) | C14: 4700 | D14: =C14*Summary!$C$5 -> 1433500 | E14: =D14*Summary!$C$6 -> 1806210 | F14: Yes
B15: Sleeve / ferrules | C15: 1165.29 | D15: =C15*Summary!$C$5 -> 355413.45 | E15: =D15*Summary!$C$6 -> 447820.95 | F15: Yes
B16: Tube swaging machine | C16: 1700 | D16: =C16*Summary!$C$5 -> 518500 | E16: =D16*Summary!$C$6 -> 653310 | F16: Yes
B17: Brick making machine | C17: 8940 | D17: =C17*Summary!$C$5 -> 2726700 | E17: =D17*Summary!$C$6 -> 3435642 | F17: No
B18: Tea making machine | C18: 2500 | D18: =C18*Summary!$C$5 -> 762500 | E18: =D18*Summary!$C$6 -> 960750 | F18: No
B19: TOTAL (whole invoice) | C19: =SUM(C10:C18) -> 21055.29 | D19: =SUM(D10:D18) -> 6421863.5 | E19: =SUM(E10:E18) -> 8091547.9
B20: Hydraulic subtotal (excl. brick + tea) | C20: =SUMIF($F$10:$F$18,"Yes",$C$10:$C$18) -> 9615.29 | D20: =C20*Summary!$C$5 -> 2932663.5 | E20: =D20*Summary!$C$6 -> 3695155.9
B22: Delivery status
B23: Items ordered | C23: 84
B24: Items NOT received | C24: 39,40,41,42,43,44,84
B25: Est. value NOT received (USD) | C25: ='Not received'!$G$12 -> 1946.1622
B26: Est. value NOT received (LKR landed) | C26: =C25*Summary!$C$5*Summary!$C$6 -> 747910.12
B28: Notes
B29: • This invoice covers a larger order than the hydraulic packing list — it also includes a brick-making machine (8,940 USD) and a tea-making machine (2,500 USD), which are NOT hydraulic and NOT in the packing list.
B30: • CIF = cost landed at Colombo port. 'LKR landed' adds the duty factor above (ex-VAT). VAT (18%) is recoverable if E&C is registered.
B31: • Exchange rate is set to your Nov-2025 payment rate. The market benchmarks on the Cost vs Market sheet reflect the CURRENT market (~LKR 335/USD).
B32: • Per-item costs are ALLOCATED from invoice group totals (the invoice does not price each line) — see method notes on the Cost vs Market sheet.

Sheet Item Register
A1: ITEM REGISTER — packing list HS25E1112W1 (84 items)
A2: Red rows = NOT received (items 39,40,41,42,43,44,84). All other items received.
A4: No | B4: Category | C4: Sub-type | D4: Spec Code | E4: Description | F4: Size | G4: Qty | H4: Unit | I4: Received | J4: Inv. group
A5: 1 | B5: Hose | C5: R1 | D5: — | E5: R1 fabric hydraulic hose, ID 6mm | F5: 1/4" | G5: 200 | H5: m | I5: Yes | J5: Rubber hose
A6: 2 | B6: Hose | C6: R1 | D6: — | E6: R1 fabric hydraulic hose, ID 8mm | F6: 5/16" | G6: 200 | H6: m | I6: Yes | J6: Rubber hose
A7: 3 | B7: Hose | C7: R1 | D7: — | E7: R1 fabric hydraulic hose, ID 10mm | F7: 3/8" | G7: 200 | H7: m | I7: Yes | J7: Rubber hose
A8: 4 | B8: Hose | C8: R2 | D8: — | E8: R2 fabric hydraulic hose, ID 6mm | F8: 1/4" | G8: 200 | H8: m | I8: Yes | J8: Rubber hose
A9: 5 | B9: Hose | C9: R2 | D9: — | E9: R2 fabric hydraulic hose, ID 8mm | F9: 5/16" | G9: 200 | H9: m | I9: Yes | J9: Rubber hose
A10: 6 | B10: Hose | C10: R2 | D10: — | E10: R2 fabric hydraulic hose, ID 10mm | F10: 3/8" | G10: 200 | H10: m | I10: Yes | J10: Rubber hose
A11: 7 | B11: Hose | C11: R2 | D11: — | E11: R2 fabric hydraulic hose, ID 13mm | F11: 1/2" | G11: 200 | H11: m | I11: Yes | J11: Rubber hose
A12: 8 | B12: Hose | C12: R2 | D12: — | E12: R2 fabric hydraulic hose, ID 16mm | F12: 5/8" | G12: 200 | H12: m | I12: Yes | J12: Rubber hose
A13: 9 | B13: Hose | C13: R2 | D13: — | E13: R2 fabric hydraulic hose, ID 19mm | F13: 3/4" | G13: 200 | H13: m | I13: Yes | J13: Rubber hose
A14: 10 | B14: Hose | C14: R2 | D14: — | E14: R2 fabric hydraulic hose, ID 25mm | F14: 1" | G14: 200 | H14: m | I14: Yes | J14: Rubber hose
A15: 11 | B15: Hose | C15: R2 | D15: — | E15: R2 fabric hydraulic hose, ID 32mm | F15: 1-1/4" | G15: 120 | H15: m | I15: Yes | J15: Rubber hose
A16: 12 | B16: Hose | C16: 4SP | D16: — | E16: EN856 4SP hydraulic hose, ID 16mm | F16: 5/8" | G16: 120 | H16: m | I16: Yes | J16: Rubber hose
... A88: 84 | B88: Machine | C88: Swaging m/c | D88: R32ELD-380V | E88: Tube swaging machine, crimp 1/4"-2" 6-51mm 4SH, 12 die sets, 4kW, 380V 3ph, 310kg | F88: 1/4"-2" | G88: 1 | H88: unit | I88: NO | J88: Machine.1700

Sheet Cost vs Market
A1: COST vs MARKET — your landed cost against local market Mid
A2: LKR, VAT-excl. Landed = CIF × duty factor (Summary). Market Mid = current local benchmark (editable, blue). Markup% = how much above your landed cost the market sells = pricing headroom.
A4: A. HOSE — 4,700 USD allocated across 15 lines by (metres × market Mid)
A5: Grade / size | B5: Metres | C5: Mkt Mid LKR/m | D5: Cost USD/m | E5: Cost LKR/m CIF | F5: Landed LKR/m | G5: Market Mid LKR/m | H5: Markup %
A6: R1 1/4" | B6: 200 | C6: 770 | D6: =4700*C6/SUMPRODUCT($B6:$B20,$C6:$C20) -> 0.37460666 | E6: =D6*Summary!$C$5 -> 114.25503 | F6: =E6*Summary!$C$6 -> 143.96134 | G6: =C6 -> 770 | H6: =IFERROR(G6/F6-1,0) -> 4.3486582
A7: R1 5/16" | B7: 200 | C7: 910 | D7: =4700*C7/SUMPRODUCT($B6:$B20,$C6:$C20) -> 0.44271696 | E7: =D7*Summary!$C$5 -> 135.02867 | F7: =E7*Summary!$C$6 -> 170.13613 | G7: =C7 -> 910 | H7: =IFERROR(G7/F7-1,0) -> 4.3486582
A8: R1 3/8" | B8: 200 | C8: 1050 | D8: =4700*C8/SUMPRODUCT($B6:$B20,$C6:$C20) -> 0.51082726 | E8: =D8*Summary!$C$5 -> 155.80231 | F8: =E8*Summary!$C$6 -> 196.31092 | G8: =C8 -> 1050 | H8: =IFERROR(G8/F8-1,0) -> 4.3486582
A9: R2 1/4" | B9: 200 | C9: 1100 | D9: =4700*C9/SUMPRODUCT($B6:$B20,$C6:$C20) -> 0.53515237 | E9: =D9*Summary!$C$5 -> 163.22147 | F9: =E9*Summary!$C$6 -> 205.65906 | G9: =C9 -> 1100 | H9: =IFERROR(G9/F9-1,0) -> 4.3486582
A10: R2 5/16" | B10: 200 | C10: 1300 | D10: =4700*C10/SUMPRODUCT($B6:$B20,$C6:$C20) -> 0.6324528 | E10: =D10*Summary!$C$5 -> 192.8981 | F10: =E10*Summary!$C$6 -> 243.05161 | G10: =C10 -> 1300 | H10: =IFERROR(G10/F10-1,0) -> 4.3486582
A11: R2 3/8" | B11: 200 | C11: 1500 | D11: =4700*C11/SUMPRODUCT($B6:$B20,$C6:$C20) -> 0.72975323 | E11: =D11*Summary!$C$5 -> 222.57474 | F11: =E11*Summary!$C$6 -> 280.44417 | G11: =C11 -> 1500 | H11: =IFERROR(G11/F11-1,0) -> 4.3486582
A12: R2 1/2" | B12: 200 | C12: 1900 | D12: =4700*C12/SUMPRODUCT($B6:$B20,$C6:$C20) -> 0.92435409 | E12: =D12*Summary!$C$5 -> 281.928 | F12: =E12*Summary!$C$6 -> 355.22928 | G12: =C12 -> 1900 | H12: =IFERROR(G12/F12-1,0) -> 4.3486582
A13: R2 5/8" | B13: 200 | C13: 2450 | D13: =4700*C13/SUMPRODUCT($B6:$B20,$C6:$C20) -> 1.1919303 | E13: =D13*Summary!$C$5 -> 363.53873 | F13: =E13*Summary!$C$6 -> 458.0588 | G13: =C13 -> 2450 | H13: =IFERROR(G13/F13-1,0) -> 4.3486582
A14: R2 3/4" | B14: 200 | C14: 3000 | D14: =4700*C14/SUMPRODUCT($B6:$B20,$C6:$C20) -> 1.4595065 | E14: =D14*Summary!$C$5 -> 445.14947 | F14: =E14*Summary!$C$6 -> 560.88833 | G14: =C14 -> 3000 | H14: =IFERROR(G14/F14-1,0) -> 4.3486582
A15: R2 1" | B15: 200 | C15: 4300 | D15: =4700*C15/SUMPRODUCT($B6:$B20,$C6:$C20) -> 2.0919593 | E15: =D15*Summary!$C$5 -> 638.04757 | F15: =E15*Summary!$C$6 -> 803.93994 | G15: =C15 -> 4300 | H15: =IFERROR(G15/F15-1,0) -> 4.3486582
A16: R2 1-1/4" | B16: 120 | C16: 6000 | D16: =4700*C16/SUMPRODUCT($B6:$B20,$C6:$C20) -> 2.9190129 | E16: =D16*Summary!$C$5 -> 890.29894 | F16: =E16*Summary!$C$6 -> 1121.7767 | G16: =C16 -> 6000 | H16: =IFERROR(G16/F16-1,0) -> 4.3486582
A17: 4SP 5/8" | B17: 120 | C17: 6130 | D17: =4700*C17/SUMPRODUCT($B6:$B20,$C6:$C20) -> 2.9822582 | E17: =D17*Summary!$C$5 -> 909.58875 | F17: =E17*Summary!$C$6 -> 1146.0818 | G17: =C17 -> 6130 | H17: =IFERROR(G17/F17-1,0) -> 4.3486582
A18: 4SH 3/4" | B18: 120 | C18: 8550 | D18: =4700*C18/SUMPRODUCT($B6:$B20,$C6:$C20) -> 4.1595934 | E18: =D18*Summary!$C$5 -> 1268.676 | F18: =E18*Summary!$C$6 -> 1598.5317 | G18: =C18 -> 8550 | H18: =IFERROR(G18/F18-1,0) -> 4.3486582
A19: 4SH 1" | B19: 120 | C19: 12260 | D19: =4700*C19/SUMPRODUCT($B6:$B20,$C6:$C20) -> 5.9645164 | E19: =D19*Summary!$C$5 -> 1819.1775 | F19: =E19*Summary!$C$6 -> 2292.1637 | G19: =C19 -> 12260 | H19: =IFERROR(G19/F19-1,0) -> 4.3486582
A20: 4SH 1-1/4" | B20: 120 | C20: 17100 | D20: =4700*C20/SUMPRODUCT($B6:$B20,$C6:$C20) -> 8.3191868 | E20: =D20*Summary!$C$5 -> 2537.352 | F20: =E20*Summary!$C$6 -> 3197.0635 | G20: =C20 -> 17100 | H20: =IFERROR(G20/F20-1,0) -> 4.3486582
A21: Hose total / avg | B21: =SUM(B6:B20) -> 2600 | F21: =SUMPRODUCT(B6:B20,F6:F20)/SUM(B6:B20) -> 694.69615 | G21: =SUMPRODUCT(B6:B20,G6:G20)/SUM(B6:B20) -> 3715.6923 | H21: =G21/F21-1 -> 4.3486582
A23: B. FITTINGS & MACHINE — allocated from invoice group totals (avg cost per piece)
A24: Category | B24: Pcs | C24: Group USD | D24: Alloc USD | E24: Cost USD/pc | F24: Cost LKR/pc | G24: Landed LKR/pc | H24: (market varies)
A25: Ferrule 1SN (90110) | B25: 90 | C25: 1165.29 | D25: 233.06 | E25: =D25/B25 -> 2.5895556 | F25: =E25*Summary!$C$5 -> 789.81444 | G25: =F25*Summary!$C$6 -> 995.1662
A26: Ferrule 2SN (00210) | B26: 240 | C26: 1165.29 | D26: 621.49 | E26: =D26/B26 -> 2.5895417 | F26: =E26*Summary!$C$5 -> 789.81021 | G26: =F26*Summary!$C$6 -> 995.16086
A27: Ferrule spiral (00400) | B27: 120 | C27: 1165.29 | D27: 310.74 | E27: =D27/B27 -> 2.5895 | F27: =E27*Summary!$C$5 -> 789.7975 | G27: =F27*Summary!$C$6 -> 995.14485
A28: Unions grp 828 (31-49) | B28: 925 | C28: 828 | D28: 828 | E28: =D28/B28 -> 0.89513514 | F28: =E28*Summary!$C$5 -> 273.01622 | G28: =F28*Summary!$C$6 -> 344.00043
A29: Unions grp 1032 (50-68) | B29: 1260 | C29: 1032 | D29: 1032 | E29: =D29/B29 -> 0.81904762 | F29: =E29*Summary!$C$5 -> 249.80952 | G29: =F29*Summary!$C$6 -> 314.76
A30: Unions grp 70 (69-78) | B30: 90 | C30: 70 | D30: 70 | E30: =D30/B30 -> 0.77777778 | F30: =E30*Summary!$C$5 -> 237.22222 | G30: =F30*Summary!$C$6 -> 298.9
A31: Flanges grp 120 (79-83) | B31: 50 | C31: 120 | D31: 120 | E31: =D31/B31 -> 2.4 | F31: =E31*Summary!$C$5 -> 732 | G31: =F31*Summary!$C$6 -> 922.32
A32: Swaging machine | B32: 1 | C32: 1700 | D32: 1700 | E32: =D32/B32 -> 1700 | F32: =E32*Summary!$C$5 -> 518500 | G32: =F32*Summary!$C$6 -> 653310
A34: Method & caveats
A35: • The invoice prices GROUPS, not individual lines, so every per-item cost here is an ALLOCATION, not the supplier's exact figure.
A36: • Hose: the 4,700 USD is split across the 15 lines in proportion to (metres × market Mid), so the cost distribution follows the market price shape. This makes the markup% roughly uniform across hose — the reliable insight is the AGGREGATE gap, not line-by-line.
A37: • Fittings: each invoice group's USD is divided equally per piece within the group (a G1-1/4" fitting really costs more than a G1/4", so treat small vs large within a group as indicative only).
A38: • The large markup vs market Mid means either local retail margins on imported hose are very high, OR our market Mid benchmark is on the high side. Either way, YOUR landed cost is now the ground truth — consider revising the rate-card Mid down toward it.
A39: • Ferrule spiral (00400) and larger sizes physically cost more than the equal-per-piece split shows; refine when you get a priced invoice.

Sheet Unit Prices (bill)
A1: UNIT PRICE LIST — unions · ferrules · flanges (bill-ready)
A2: Per-piece COST allocated from each invoice group total by (size × fitting-type) weight. Cost = CIF × duty (Summary). SELL = market benchmark / estimate (blue, editable). Margin = Sell ÷ Cost − 1. LKR, VAT-excl.
A4: No | B4: Type | C4: Code | D4: Size | E4: Description | F4: Qty | G4: Weight | H4: Cost USD | I4: Cost LKR | J4: Sell LKR | K4: Margin | L4: Recv
A5: FERRULES — sleeve group | G5: Grp USD→ | H5: 1165.29
A6: 16 | B6: 1SN | C6: 00110-04 | D6: 1/4" | E6: Ferrule R1AT/1SN, hose ID 6mm, carbon steel | F6: 30 | G6: 153 | H6: =$H$5*G6/SUMPRODUCT($F$6:$F$20,$G$6:$G$20) -> 0.57006993 | I6: =H6*Summary!$C$5*Summary!$C$6 -> 219.07787 | J6: 351 | K6: =IFERROR(J6/I6-1,0) -> 0.60217002 | L6: Yes
A7: 17 | B7: 1SN | C7: 00110-05 | D7: 5/16" | E7: Ferrule R1AT/1SN, hose ID 8mm, carbon steel | F7: 30 | G7: 170 | H7: =$H$5*G7/SUMPRODUCT($F$6:$F$20,$G$6:$G$20) -> 0.63341103 | I7: =H7*Summary!$C$5*Summary!$C$6 -> 243.41986 | J7: 389 | K7: =IFERROR(J7/I7-1,0) -> 0.59806189 | L7: Yes
A8: 18 | B8: 1SN | C8: 00110-06 | D8: 3/8" | E8: Ferrule R1AT/1SN, hose ID 10mm, carbon steel | F8: 30 | G8: 187 | H8: =$H$5*G8/SUMPRODUCT($F$6:$F$20,$G$6:$G$20) -> 0.69675213 | I8: =H8*Summary!$C$5*Summary!$C$6 -> 267.76185 | J8: 428 | K8: =IFERROR(J8/I8-1,0) -> 0.59843535 | L8: Yes
A9: 19 | B9: 2SN | C9: 00210-04 | D9: 1/4" | E9: Ferrule R2AT/2SN, hose ID 6mm, carbon steel | F9: 30 | G9: 180 | H9: =$H$5*G9/SUMPRODUCT($F$6:$F$20,$G$6:$G$20) -> 0.6706705 | I9: =H9*Summary!$C$5*Summary!$C$6 -> 257.73867 | J9: 412 | K9: =IFERROR(J9/I9-1,0) -> 0.59851835 | L9: Yes
A10: 20 | B10: 2SN | C10: 00210-05 | D10: 5/16" | E10: Ferrule R2AT/2SN, hose ID 8mm, carbon steel | F10: 30 | G10: 200 | H10: =$H$5*G10/SUMPRODUCT($F$6:$F$20,$G$6:$G$20) -> 0.74518945 | I10: =H10*Summary!$C$5*Summary!$C$6 -> 286.37631 | J10: 458 | K10: =IFERROR(J10/I10-1,0) -> 0.59929433 | L10: Yes
A11: 21 | B11: 2SN | C11: 00210-06 | D11: 3/8" | E11: Ferrule R2AT/2SN, hose ID 10mm, carbon steel | F11: 30 | G11: 220 | H11: =$H$5*G11/SUMPRODUCT($F$6:$F$20,$G$6:$G$20) -> 0.81970839 | I11: =H11*Summary!$C$5*Summary!$C$6 -> 315.01394 | J11: 504 | K11: =IFERROR(J11/I11-1,0) -> 0.59992922 | L11: Yes
A12: 22 | B12: 2SN | C12: 00210-08 | D12: 1/2" | E12: Ferrule R2AT/2SN, hose ID 12mm, carbon steel | F12: 30 | G12: 290 | H12: =$H$5*G12/SUMPRODUCT($F$6:$F$20,$G$6:$G$20) -> 1.0805247 | I12: =H12*Summary!$C$5*Summary!$C$6 -> 415.24564 | J12: 664 | K12: =IFERROR(J12/I12-1,0) -> 0.59905351 | L12: Yes
A13: 23 | B13: 2SN | C13: 00210-10 | D13: 5/8" | E13: Ferrule R2AT/2SN, hose ID 16mm, carbon steel | F13: 30 | G13: 460 | H13: =$H$5*G13/SUMPRODUCT($F$6:$F$20,$G$6:$G$20) -> 1.7139357 | I13: =H13*Summary!$C$5*Summary!$C$6 -> 658.6655 | J13: 1054 | K13: =IFERROR(J13/I13-1,0) -> 0.60020526 | L13: Yes
A14: 24 | B14: 2SN | C14: 00210-12 | D14: 3/4" | E14: Ferrule R2AT/2SN, hose ID 20mm, carbon steel | F14: 30 | G14: 650 | H14: =$H$5*G14/SUMPRODUCT($F$6:$F$20,$G$6:$G$20) -> 2.4218657 | I14: =H14*Summary!$C$5*Summary!$C$6 -> 930.72299 | J14: 1489 | K14: =IFERROR(J14/I14-1,0) -> 0.59983154 | L14: Yes
A15: 25 | B15: 2SN | C15: 00210-16 | D15: 1" | E15: Ferrule R2AT/2SN, hose ID 25mm, carbon steel | F15: 30 | G15: 1000 | H15: =$H$5*G15/SUMPRODUCT($F$6:$F$20,$G$6:$G$20) -> 3.7259472 | I15: =H15*Summary!$C$5*Summary!$C$6 -> 1431.8815 | J15: 2291 | K15: =IFERROR(J15/I15-1,0) -> 0.59999271 | L15: Yes
A16: 26 | B16: 2SN | C16: 00210-20 | D16: 1-1/4" | E16: Ferrule R2AT/2SN, hose ID 32mm, carbon steel | F16: 30 | G16: 1500 | H16: =$H$5*G16/SUMPRODUCT($F$6:$F$20,$G$6:$G$20) -> 5.5889209 | I16: =H16*Summary!$C$5*Summary!$C$6 -> 2147.8223 | J16: 3437 | K16: =IFERROR(J16/I16-1,0) -> 0.6002255 | L16: Yes
A17: 27 | B17: Spiral | C17: 00400-10 | D17: 5/8" | E17: Ferrule R9/R12/4SP-4SH, hose ID 16mm | F17: 30 | G17: 690 | H17: =$H$5*G17/SUMPRODUCT($F$6:$F$20,$G$6:$G$20) -> 2.5709036 | I17: =H17*Summary!$C$5*Summary!$C$6 -> 987.99825 | J17: 1581 | K17: =IFERROR(J17/I17-1,0) -> 0.60020526 | L17: Yes
... A20: 30 | B20: Spiral | C20: 00400-20 | D20: 1-1/4" | E20: Ferrule R9/R12/4SP-4SH, hose ID 32mm | F20: 30 | G20: 2250 | H20: =$H$5*G20/SUMPRODUCT($F$6:$F$20,$G$6:$G$20) -> 8.3833813 | I20: =H20*Summary!$C$5*Summary!$C$6 -> 3221.7334 | J20: 5155 | K20: =IFERROR(J20/I20-1,0) -> 0.60007031 | L20: Yes
E21: Subtotal — Σ(qty×cost) = group USD → | F21: =SUM(F6:F20) -> 450 | H21: =SUMPRODUCT(F6:F20,H6:H20) -> 1165.29 | I21: =SUMPRODUCT(F6:F20,I6:I20) -> 447820.95 | J21: =SUMPRODUCT(F6:F20,J6:J20) -> 716520
A23: UNIONS — group 828 (BSP straight / 90° / double-hex) | G23: Grp USD→ | H23: 828
A24: 31 | B24: BSP straight | C24: 22611-04-04 | D24: G1/4" | E24: BSP female 60° cone G1/4"x19, hose 6mm | F24: 50 | G24: 620 | H24: =$H$23*G24/SUMPRODUCT($F$24:$F$42,$G$24:$G$42) -> 0.36034114 | I24: =H24*Summary!$C$5*Summary!$C$6 -> 138.4791 | J24: 620 | K24: =IFERROR(J24/I24-1,0) -> 3.47721 | L24: Yes
A25: 32 | B25: BSP straight | C25: 22611-06-04 | D25: G3/8" | E25: BSP female 60° cone G3/8"x19, hose 6mm | F25: 50 | G25: 720 | H25: =$H$23*G25/SUMPRODUCT($F$24:$F$42,$G$24:$G$42) -> 0.41846067 | I25: =H25*Summary!$C$5*Summary!$C$6 -> 160.81444 | J25: 720 | K25: =IFERROR(J25/I25-1,0) -> 3.47721 | L25: Yes
A26: 33 | B26: BSP straight | C26: 22611-06-06 | D26: G3/8" | E26: BSP female 60° cone G3/8"x19, hose 10mm | F26: 50 | G26: 720 | H26: =$H$23*G26/SUMPRODUCT($F$24:$F$42,$G$24:$G$42) -> 0.41846067 | I26: =H26*Summary!$C$5*Summary!$C$6 -> 160.81444 | J26: 720 | K26: =IFERROR(J26/I26-1,0) -> 3.47721 | L26: Yes
A27: 34 | B27: BSP straight | C27: 22611-06-08 | D27: G3/8" | E27: BSP female 60° cone G3/8"x19, hose 12mm | F27: 50 | G27: 720 | H27: =$H$23*G27/SUMPRODUCT($F$24:$F$42,$G$24:$G$42) -> 0.41846067 | I27: =H27*Summary!$C$5*Summary!$C$6 -> 160.81444 | J27: 720 | K27: =IFERROR(J27/I27-1,0) -> 3.47721 | L27: Yes
A28: 35 | B28: BSP straight | C28: 22611-08-06T | D28: G1/2" | E28: BSP female 60° cone G1/2"x14, hose 10mm | F28: 50 | G28: 950 | H28: =$H$23*G28/SUMPRODUCT($F$24:$F$42,$G$24:$G$42) -> 0.55213561 | I28: =H28*Summary!$C$5*Summary!$C$6 -> 212.18572 | J28: 950 | K28: =IFERROR(J28/I28-1,0) -> 3.47721 | L28: Yes
A29: 36 | B29: BSP straight | C29: 22611-08-08 | D29: G1/2" | E29: BSP female 60° cone G1/2"x14, hose 12mm | F29: 50 | G29: 950 | H29: =$H$23*G29/SUMPRODUCT($F$24:$F$42,$G$24:$G$42) -> 0.55213561 | I29: =H29*Summary!$C$5*Summary!$C$6 -> 212.18572 | J29: 950 | K29: =IFERROR(J29/I29-1,0) -> 3.47721 | L29: Yes
A30: 37 | B30: BSP straight | C30: 22611-10-10 | D30: G5/8" | E30: BSP female 60° cone G5/8"x14, hose 16mm | F30: 50 | G30: 1250 | H30: =$H$23*G30/SUMPRODUCT($F$24:$F$42,$G$24:$G$42) -> 0.72649423 | I30: =H30*Summary!$C$5*Summary!$C$6 -> 279.19173 | J30: 1250 | K30: =IFERROR(J30/I30-1,0) -> 3.47721 | L30: Yes
A31: 38 | B31: BSP straight | C31: 22611-12-12 | D31: G3/4" | E31: BSP female 60° cone G3/4"x14, hose 20mm | F31: 50 | G31: 1600 | H31: =$H$23*G31/SUMPRODUCT($F$24:$F$42,$G$24:$G$42) -> 0.92991261 | I31: =H31*Summary!$C$5*Summary!$C$6 -> 357.36542 | J31: 1600 | K31: =IFERROR(J31/I31-1,0) -> 3.47721 | L31: Yes
A32: 39 | B32: BSP straight | C32: 22611-16-16 | D32: G1" | E32: BSP female 60° cone G1"x11, hose 25mm | F32: 50 | G32: 2600 | H32: =$H$23*G32/SUMPRODUCT($F$24:$F$42,$G$24:$G$42) -> 1.511108 | I32: =H32*Summary!$C$5*Summary!$C$6 -> 580.7188 | J32: 2600 | K32: =IFERROR(J32/I32-1,0) -> 3.47721 | L32: NO
A33: 40 | B33: BSP straight | C33: 22611-20-20W | D33: G1-1/4" | E33: BSP female 60° cone G1-1/4"x11, hose 32mm | F33: 25 | G33: 3900 | H33: =$H$23*G33/SUMPRODUCT($F$24:$F$42,$G$24:$G$42) -> 2.266662 | I33: =H33*Summary!$C$5*Summary!$C$6 -> 871.0782 | J33: 3900 | K33: =IFERROR(J33/I33-1,0) -> 3.47721 | L33: NO
A34: 41 | B34: BSP 90° | C34: 22691-04-04 | D34: G1/4" | E34: 90° BSP female 60° cone G1/4"x19, hose 6mm | F34: 50 | G34: 1209 | H34: =$H$23*G34/SUMPRODUCT($F$24:$F$42,$G$24:$G$42) -> 0.70266522 | I34: =H34*Summary!$C$5*Summary!$C$6 -> 270.03424 | J34: 1209 | K34: =IFERROR(J34/I34-1,0) -> 3.47721 | L34: NO
A35: 42 | B35: BSP 90° | C35: 22691-06-06 | D35: G3/8" | E35: 90° BSP female 60° cone G3/8"x19, hose 10mm | F35: 50 | G35: 1404 | H35: =$H$23*G35/SUMPRODUCT($F$24:$F$42,$G$24:$G$42) -> 0.81599832 | I35: =H35*Summary!$C$5*Summary!$C$6 -> 313.58815 | J35: 1404 | K35: =IFERROR(J35/I35-1,0) -> 3.47721 | L35: NO
... A42: 49 | B42: BSP dbl-hex | C42: 22611D-20-20W | D42: G1-1/4" | E42: BSP female 60° cone dbl-hex G1-1/4"x11, hose 32mm | F42: 50 | G42: 4485 | H42: =$H$23*G42/SUMPRODUCT($F$24:$F$42,$G$24:$G$42) -> 2.6066613 | I42: =H42*Summary!$C$5*Summary!$C$6 -> 1001.7399 | J42: 4485 | K42: =IFERROR(J42/I42-1,0) -> 3.47721 | L42: Yes
E43: Subtotal — Σ(qty×cost) = group USD → | F43: =SUM(F24:F42) -> 925 | H43: =SUMPRODUCT(F24:F42,H24:H42) -> 828 | I43: =SUMPRODUCT(F24:F42,I24:I42) -> 318200.4 | J43: =SUMPRODUCT(F24:F42,J24:J42) -> 1424650
A45: UNIONS — group 1032 (BSP straight / 90° / welding fitting) | G45: Grp USD→ | H45: 1032
A46: 50 | B46: BSP straight | C46: 22612-10-10 | D46: G5/8" | E46: BSP female 60° cone G5/8"x14, hose 16mm | F46: 50 | G46: 1250 | H46: =$H$45*G46/SUMPRODUCT($F$46:$F$64,$G$46:$G$64) -> 0.82033672 | I46: =H46*Summary!$C$5*Summary!$C$6 -> 315.2554 | J46: 1250 | K46: =IFERROR(J46/I46-1,0) -> 2.9650391 | L46: Yes
A47: 51 | B47: BSP straight | C47: 22612-12-12 | D47: G3/4" | E47: BSP female 60° cone G3/4"x14, hose 20mm | F47: 100 | G47: 1600 | H47: =$H$45*G47/SUMPRODUCT($F$46:$F$64,$G$46:$G$64) -> 1.050031 | I47: =H47*Summary!$C$5*Summary!$C$6 -> 403.52691 | J47: 1600 | K47: =IFERROR(J47/I47-1,0) -> 2.9650391 | L47: Yes
A48: 52 | B48: BSP straight | C48: 22612-16-16 | D48: G1" | E48: BSP female 60° cone G1"x11, hose 25mm | F48: 50 | G48: 2600 | H48: =$H$45*G48/SUMPRODUCT($F$46:$F$64,$G$46:$G$64) -> 1.7063004 | I48: =H48*Summary!$C$5*Summary!$C$6 -> 655.73123 | J48: 2600 | K48: =IFERROR(J48/I48-1,0) -> 2.9650391 | L48: Yes
A49: 53 | B49: BSP straight | C49: 22612-20-20 | D49: G1-1/4" | E49: BSP female 60° cone G1-1/4"x11, hose 32mm | F49: 25 | G49: 3900 | H49: =$H$45*G49/SUMPRODUCT($F$46:$F$64,$G$46:$G$64) -> 2.5594506 | I49: =H49*Summary!$C$5*Summary!$C$6 -> 983.59685 | J49: 3900 | K49: =IFERROR(J49/I49-1,0) -> 2.9650391 | L49: Yes
A50: 54 | B50: BSP 90° | C50: 22692-04-04 | D50: G1/4" | E50: 90° BSP female 60° cone G1/4"x19, hose 6mm | F50: 50 | G50: 1209 | H50: =$H$45*G50/SUMPRODUCT($F$46:$F$64,$G$46:$G$64) -> 0.79342968 | I50: =H50*Summary!$C$5*Summary!$C$6 -> 304.91502 | J50: 1209 | K50: =IFERROR(J50/I50-1,0) -> 2.9650391 | L50: Yes
A51: 55 | B51: BSP 90° | C51: 22692-06-06 | D51: G3/8" | E51: 90° BSP female 60° cone G3/8"x19, hose 10mm | F51: 50 | G51: 1404 | H51: =$H$45*G51/SUMPRODUCT($F$46:$F$64,$G$46:$G$64) -> 0.9214022 | I51: =H51*Summary!$C$5*Summary!$C$6 -> 354.09487 | J51: 1404 | K51: =IFERROR(J51/I51-1,0) -> 2.9650391 | L51: Yes
...

Sheet Crimping Charges
A1: CRIMPING CHARGES — market rate per end vs your internal cost
A2: LKR, VAT-excl, PER END. Market = standalone per-end crimp fee (shops usually bundle it into a finished assembly). Internal cost = machine amortization + labour + consumables. Bill margin = market Mid − internal cost.
A4: A. Internal cost model — edit the yellow cells
A5: Crimping machine cost (LKR landed) | B5: =1700*Summary!$C$5*Summary!$C$6 -> 653310 | C5: R32ELD ordered @1,700 USD (edit to your machine)
A6: Machine life (years) | B6: 7 | C6: straight-line amortization
A7: Crimp ends per year | B7: 800 | C7: ≈400 assemblies × 2 ends
A8: → Machine amort per end (LKR) | B8: =B5/(B6*B7) -> 116.6625 | C8: auto
A9: Labour rate, burdened (LKR/hr) | B9: 1400 | C9: salary + EPF/ETF + OT + overhead
A10: Consumables / dies per end (LKR) | B10: 30 | C10: die wear, cut-off blade
A11: Power per end (LKR) | B11: 3 | C11: 4 kW × short cycle
A13: B. Per end — market crimp charge & your margin
A14: Size | B14: Time min | C14: Labour /end | D14: Amort /end | E14: Consum+ power | F14: INTERNAL cost/end | G14: Mkt Low | H14: Mkt Mid | I14: Mkt High | J14: Margin/end (at Mid) | K14: Margin %
A15: 1/4" | B15: 6 | C15: =B15/60*$B$9 -> 140 | D15: =$B$8 -> 116.6625 | E15: =$B$10+$B$11 -> 33 | F15: =C15+D15+E15 -> 289.6625 | G15: 250 | H15: 650 | I15: 1800 | J15: =H15-F15 -> 360.3375 | K15: =IFERROR((H15-F15)/F15,0) -> 1.2439909
A16: 5/16" | B16: 6 | C16: =B16/60*$B$9 -> 140 | D16: =$B$8 -> 116.6625 | E16: =$B$10+$B$11 -> 33 | F16: =C16+D16+E16 -> 289.6625 | G16: 250 | H16: 650 | I16: 1800 | J16: =H16-F16 -> 360.3375 | K16: =IFERROR((H16-F16)/F16,0) -> 1.2439909
A17: 3/8" | B17: 7 | C17: =B17/60*$B$9 -> 163.33333 | D17: =$B$8 -> 116.6625 | E17: =$B$10+$B$11 -> 33 | F17: =C17+D17+E17 -> 312.99583 | G17: 250 | H17: 650 | I17: 1800 | J17: =H17-F17 -> 337.00417 | K17: =IFERROR((H17-F17)/F17,0) -> 1.076705
A18: 1/2" | B18: 8 | C18: =B18/60*$B$9 -> 186.66667 | D18: =$B$8 -> 116.6625 | E18: =$B$10+$B$11 -> 33 | F18: =C18+D18+E18 -> 336.32917 | G18: 280 | H18: 700 | I18: 1900 | J18: =H18-F18 -> 363.67083 | K18: =IFERROR((H18-F18)/F18,0) -> 1.0812944
A19: 5/8" | B19: 9 | C19: =B19/60*$B$9 -> 210 | D19: =$B$8 -> 116.6625 | E19: =$B$10+$B$11 -> 33 | F19: =C19+D19+E19 -> 359.6625 | G19: 380 | H19: 850 | I19: 2200 | J19: =H19-F19 -> 490.3375 | K19: =IFERROR((H19-F19)/F19,0) -> 1.3633267
A20: 3/4" | B20: 10 | C20: =B20/60*$B$9 -> 233.33333 | D20: =$B$8 -> 116.6625 | E20: =$B$10+$B$11 -> 33 | F20: =C20+D20+E20 -> 382.99583 | G20: 450 | H20: 950 | I20: 2500 | J20: =H20-F20 -> 567.00417 | K20: =IFERROR((H20-F20)/F20,0) -> 1.4804447
A21: 1" | B21: 13 | C21: =B21/60*$B$9 -> 303.33333 | D21: =$B$8 -> 116.6625 | E21: =$B$10+$B$11 -> 33 | F21: =C21+D21+E21 -> 452.99583 | G21: 650 | H21: 1350 | I21: 3500 | J21: =H21-F21 -> 897.00417 | K21: =IFERROR((H21-F21)/F21,0) -> 1.9801599
A22: 1-1/4" | B22: 16 | C22: =B22/60*$B$9 -> 373.33333 | D22: =$B$8 -> 116.6625 | E22: =$B$10+$B$11 -> 33 | F22: =C22+D22+E22 -> 522.99583 | G22: 900 | H22: 1800 | I22: 4500 | J22: =H22-F22 -> 1277.0042 | K22: =IFERROR((H22-F22)/F22,0) -> 2.44171
A24: How to use · notes
A25: • To bill a hose assembly: parts (Unit Prices sheet) + crimping (this sheet) × number of ends + hose. A 2-ferrule / 2-union assembly = 2 crimp ends, so charge 2 × the per-end rate.
A26: • Charge at market Mid for a clean margin; the 'Low' column is where small shops sit (often waived if the customer buys parts). 'High' is branded shops with a test certificate.
A27: • Internal cost is dominated by LABOUR, not the machine — at 800 ends/yr the machine amortizes to ~120 LKR/end. The more ends you run, the lower the amort (edit 'ends per year' to see it).
A28: • Spiral hose (4SP/4SH) and large bore take longer (skiving) — the higher time on 1" / 1-1/4" reflects that; raise it further for 4SH.
A29: • Machine cost defaults to the ordered R32ELD (1,700 USD landed). It was NOT received in this shipment — edit the cell to your actual machine, or set it to 0 if crimping on an existing paid-off machine.
A30: • These market rates are benchmarks (SL shops rarely publish a standalone crimp fee) — confirm against a couple of local quotes.

Sheet Not received
A1: NOT RECEIVED — items to claim / follow up with supplier
A2: Items short-shipped against packing list HS25E1112W1. Item 84 value is exact (own invoice line); connector values are estimated (equal per-piece within the 828 USD group).
A4: No | B4: Spec Code | C4: Description | D4: Size | E4: Qty | F4: Unit | G4: Est. USD | H4: Basis
A5: 39 | B5: 22611-16-16 | C5: BSP female 60° cone G1"x11, hose 25mm | D5: G1" | E5: 50 | F5: pc | G5: =828/925*E5 -> 44.756757 | H5: est. per-piece (828/925)
A6: 40 | B6: 22611-20-20W | C6: BSP female 60° cone G1-1/4"x11, hose 32mm | D6: G1-1/4" | E6: 25 | F6: pc | G6: =828/925*E6 -> 22.378378 | H6: est. per-piece (828/925)
A7: 41 | B7: 22691-04-04 | C7: 90° BSP female 60° cone G1/4"x19, hose 6mm | D7: G1/4" | E7: 50 | F7: pc | G7: =828/925*E7 -> 44.756757 | H7: est. per-piece (828/925)
A8: 42 | B8: 22691-06-06 | C8: 90° BSP female 60° cone G3/8"x19, hose 10mm | D8: G3/8" | E8: 50 | F8: pc | G8: =828/925*E8 -> 44.756757 | H8: est. per-piece (828/925)
A9: 43 | B9: 22691-08-08 | C9: 90° BSP female 60° cone G1/2"x14, hose 12mm | D9: G1/2" | E9: 50 | F9: pc | G9: =828/925*E9 -> 44.756757 | H9: est. per-piece (828/925)
A10: 44 | B10: 22611D-04-04 | C10: BSP female 60° cone dbl-hex G1/4"x19, hose 6mm | D10: G1/4" | E10: 50 | F10: pc | G10: =828/925*E10 -> 44.756757 | H10: est. per-piece (828/925)
A11: 84 | B11: R32ELD-380V | C11: Tube swaging machine, crimp 1/4"-2" 6-51mm 4SH, 12 die sets, 4kW, 380V 3ph, 310kg | D11: 1/4"-2" | E11: 1 | F11: unit | G11: 1700 | H11: exact — invoice line
C12: TOTAL estimated value not received | G12: =SUM(G5:G11) -> 1946.1622 | H12: USD
C13: LKR landed (rate × duty, from Summary) | G13: =G12*Summary!$C$5*Summary!$C$6 -> 747910.12
